
[notice] A new release of pip is available: 24.0 -> 24.3.1
[notice] To update, run: pip install --upgrade pip
Traceback (most recent call last):
  File "/scratch/mjd9571/VentureAI/myenv/lib/python3.11/site-packages/torch/distributed/run.py", line 677, in determine_local_world_size
    return int(nproc_per_node)
           ^^^^^^^^^^^^^^^^^^^
ValueError: invalid literal for int() with base 10: '=4'

The above exception was the direct cause of the following exception:

Traceback (most recent call last):
  File "/scratch/mjd9571/VentureAI/myenv/bin/torchrun", line 8, in <module>
    sys.exit(main())
             ^^^^^^
  File "/scratch/mjd9571/VentureAI/myenv/lib/python3.11/site-packages/torch/distributed/elastic/multiprocessing/errors/__init__.py", line 355, in wrapper
    return f(*args, **kwargs)
           ^^^^^^^^^^^^^^^^^^
  File "/scratch/mjd9571/VentureAI/myenv/lib/python3.11/site-packages/torch/distributed/run.py", line 919, in main
    run(args)
  File "/scratch/mjd9571/VentureAI/myenv/lib/python3.11/site-packages/torch/distributed/run.py", line 909, in run
    config, cmd, cmd_args = config_from_args(args)
                            ^^^^^^^^^^^^^^^^^^^^^^
  File "/scratch/mjd9571/VentureAI/myenv/lib/python3.11/site-packages/torch/distributed/run.py", line 790, in config_from_args
    nproc_per_node = determine_local_world_size(args.nproc_per_node)
                     ^^^^^^^^^^^^^^^^^^^^^^^^^^^^^^^^^^^^^^^^^^^^^^^
  File "/scratch/mjd9571/VentureAI/myenv/lib/python3.11/site-packages/torch/distributed/run.py", line 706, in determine_local_world_size
    raise ValueError(
ValueError: Unsupported nproc_per_node value: =4
