
[notice] A new release of pip is available: 24.0 -> 24.3.1
[notice] To update, run: pip install --upgrade pip
.env: line 1: HUGGING_FACE_HUB_TOKEN: command not found
.env: line 2: OPENAI_API_KEY: command not found
W1208 20:15:33.513000 1020988 torch/distributed/run.py:793] 
W1208 20:15:33.513000 1020988 torch/distributed/run.py:793] *****************************************
W1208 20:15:33.513000 1020988 torch/distributed/run.py:793] Setting OMP_NUM_THREADS environment variable for each process to be 1 in default, to avoid your system being overloaded, please further tune the variable for optimal performance in your application as needed. 
W1208 20:15:33.513000 1020988 torch/distributed/run.py:793] *****************************************
Traceback (most recent call last):
  File "/scratch/mjd9571/VentureAI/fine_tuning/llamainstruct.py", line 19, in <module>
Traceback (most recent call last):
  File "/scratch/mjd9571/VentureAI/fine_tuning/llamainstruct.py", line 19, in <module>
    load_dotenv()
    ^^^^^^^    ^load_dotenv()^
^^
 NameError :  name 'load_dotenv' is not defined ^^^^^^^^^^^

NameError: name 'load_dotenv' is not defined
Traceback (most recent call last):
  File "/scratch/mjd9571/VentureAI/fine_tuning/llamainstruct.py", line 19, in <module>
Traceback (most recent call last):
  File "/scratch/mjd9571/VentureAI/fine_tuning/llamainstruct.py", line 19, in <module>
    load_dotenv()
    ^^^^^^^^^^^
NameError: name 'load_dotenv' is not defined    load_dotenv()

    ^^^^^^^^^^^
NameError: name 'load_dotenv' is not defined
W1208 20:16:28.521000 1020988 torch/distributed/elastic/multiprocessing/api.py:897] Sending process 1021003 closing signal SIGTERM
W1208 20:16:28.522000 1020988 torch/distributed/elastic/multiprocessing/api.py:897] Sending process 1021004 closing signal SIGTERM
W1208 20:16:28.523000 1020988 torch/distributed/elastic/multiprocessing/api.py:897] Sending process 1021006 closing signal SIGTERM
E1208 20:16:28.595000 1020988 torch/distributed/elastic/multiprocessing/api.py:869] failed (exitcode: 1) local_rank: 2 (pid: 1021005) of binary: /scratch/mjd9571/VentureAI/myenv/bin/python
Traceback (most recent call last):
  File "/scratch/mjd9571/VentureAI/myenv/bin/torchrun", line 8, in <module>
    sys.exit(main())
             ^^^^^^
  File "/scratch/mjd9571/VentureAI/myenv/lib/python3.11/site-packages/torch/distributed/elastic/multiprocessing/errors/__init__.py", line 355, in wrapper
    return f(*args, **kwargs)
           ^^^^^^^^^^^^^^^^^^
  File "/scratch/mjd9571/VentureAI/myenv/lib/python3.11/site-packages/torch/distributed/run.py", line 919, in main
    run(args)
  File "/scratch/mjd9571/VentureAI/myenv/lib/python3.11/site-packages/torch/distributed/run.py", line 910, in run
    elastic_launch(
  File "/scratch/mjd9571/VentureAI/myenv/lib/python3.11/site-packages/torch/distributed/launcher/api.py", line 138, in __call__
    return launch_agent(self._config, self._entrypoint, list(args))
           ^^^^^^^^^^^^^^^^^^^^^^^^^^^^^^^^^^^^^^^^^^^^^^^^^^^^^^^^
  File "/scratch/mjd9571/VentureAI/myenv/lib/python3.11/site-packages/torch/distributed/launcher/api.py", line 269, in launch_agent
    raise ChildFailedError(
torch.distributed.elastic.multiprocessing.errors.ChildFailedError: 
============================================================
llamainstruct.py FAILED
------------------------------------------------------------
Failures:
  <NO_OTHER_FAILURES>
------------------------------------------------------------
Root Cause (first observed failure):
[0]:
  time      : 2024-12-08_20:16:28
  host      : gr002.hpc.nyu.edu
  rank      : 2 (local_rank: 2)
  exitcode  : 1 (pid: 1021005)
  error_file: <N/A>
  traceback : To enable traceback see: https://pytorch.org/docs/stable/elastic/errors.html
============================================================
