
[notice] A new release of pip is available: 24.0 -> 24.3.1
[notice] To update, run: pip install --upgrade pip
.env: line 1: HUGGING_FACE_HUB_TOKEN: command not found
.env: line 2: OPENAI_API_KEY: command not found
W1208 17:25:18.242000 3559354 torch/distributed/run.py:793] 
W1208 17:25:18.242000 3559354 torch/distributed/run.py:793] *****************************************
W1208 17:25:18.242000 3559354 torch/distributed/run.py:793] Setting OMP_NUM_THREADS environment variable for each process to be 1 in default, to avoid your system being overloaded, please further tune the variable for optimal performance in your application as needed. 
W1208 17:25:18.242000 3559354 torch/distributed/run.py:793] *****************************************
[rank0]: Traceback (most recent call last):
[rank0]:   File "/scratch/mjd9571/VentureAI/myenv/lib/python3.11/site-packages/huggingface_hub/utils/_http.py", line 406, in hf_raise_for_status
[rank0]:     response.raise_for_status()
[rank0]:   File "/scratch/mjd9571/VentureAI/myenv/lib/python3.11/site-packages/requests/models.py", line 1024, in raise_for_status
[rank0]:     raise HTTPError(http_error_msg, response=self)
[rank0]: requests.exceptions.HTTPError: 401 Client Error: Unauthorized for url: https://huggingface.co/meta-llama/Llama-3.1-8B-Instruct/resolve/main/config.json

[rank0]: The above exception was the direct cause of the following exception:

[rank0]: Traceback (most recent call last):
[rank0]:   File "/scratch/mjd9571/VentureAI/myenv/lib/python3.11/site-packages/transformers/utils/hub.py", line 403, in cached_file
[rank0]:     resolved_file = hf_hub_download(
[rank0]:                     ^^^^^^^^^^^^^^^^
[rank0]:   File "/scratch/mjd9571/VentureAI/myenv/lib/python3.11/site-packages/huggingface_hub/utils/_validators.py", line 114, in _inner_fn
[rank0]:     return fn(*args, **kwargs)
[rank0]:            ^^^^^^^^^^^^^^^^^^^
[rank0]:   File "/scratch/mjd9571/VentureAI/myenv/lib/python3.11/site-packages/huggingface_hub/file_download.py", line 862, in hf_hub_download
[rank0]:     return _hf_hub_download_to_cache_dir(
[rank0]:            ^^^^^^^^^^^^^^^^^^^^^^^^^^^^^^
[rank0]:   File "/scratch/mjd9571/VentureAI/myenv/lib/python3.11/site-packages/huggingface_hub/file_download.py", line 969, in _hf_hub_download_to_cache_dir
[rank0]:     _raise_on_head_call_error(head_call_error, force_download, local_files_only)
[rank0]:   File "/scratch/mjd9571/VentureAI/myenv/lib/python3.11/site-packages/huggingface_hub/file_download.py", line 1484, in _raise_on_head_call_error
[rank0]:     raise head_call_error
[rank0]:   File "/scratch/mjd9571/VentureAI/myenv/lib/python3.11/site-packages/huggingface_hub/file_download.py", line 1376, in _get_metadata_or_catch_error
[rank0]:     metadata = get_hf_file_metadata(
[rank0]:                ^^^^^^^^^^^^^^^^^^^^^
[rank0]:   File "/scratch/mjd9571/VentureAI/myenv/lib/python3.11/site-packages/huggingface_hub/utils/_validators.py", line 114, in _inner_fn
[rank0]:     return fn(*args, **kwargs)
[rank0]:            ^^^^^^^^^^^^^^^^^^^
[rank0]:   File "/scratch/mjd9571/VentureAI/myenv/lib/python3.11/site-packages/huggingface_hub/file_download.py", line 1296, in get_hf_file_metadata
[rank0]:     r = _request_wrapper(
[rank0]:         ^^^^^^^^^^^^^^^^^
[rank0]:   File "/scratch/mjd9571/VentureAI/myenv/lib/python3.11/site-packages/huggingface_hub/file_download.py", line 277, in _request_wrapper
[rank0]:     response = _request_wrapper(
[rank0]:                ^^^^^^^^^^^^^^^^^
[rank0]:   File "/scratch/mjd9571/VentureAI/myenv/lib/python3.11/site-packages/huggingface_hub/file_download.py", line 301, in _request_wrapper
[rank0]:     hf_raise_for_status(response)
[rank0]:   File "/scratch/mjd9571/VentureAI/myenv/lib/python3.11/site-packages/huggingface_hub/utils/_http.py", line 423, in hf_raise_for_status
[rank0]:     raise _format(GatedRepoError, message, response) from e
[rank0]: huggingface_hub.errors.GatedRepoError: 401 Client Error. (Request ID: Root=1-67561cd2-54b7270a10117f1072dd3532;b521bbe2-302c-470c-8f96-63a57421d8f2)

[rank0]: Cannot access gated repo for url https://huggingface.co/meta-llama/Llama-3.1-8B-Instruct/resolve/main/config.json.
[rank0]: Access to model meta-llama/Llama-3.1-8B-Instruct is restricted. You must have access to it and be authenticated to access it. Please log in.

[rank0]: The above exception was the direct cause of the following exception:

[rank0]: Traceback (most recent call last):
[rank0]:   File "/scratch/mjd9571/VentureAI/fine_tuning/llamainstruct.py", line 619, in <module>
[rank0]:     main()
[rank0]:   File "/scratch/mjd9571/VentureAI/fine_tuning/llamainstruct.py", line 254, in main
[rank0]:     tokenizer = AutoTokenizer.from_pretrained(model_name)
[rank0]:                 ^^^^^^^^^^^^^^^^^^^^^^^^^^^^^^^^^^^^^^^^^
[rank0]:   File "/scratch/mjd9571/VentureAI/myenv/lib/python3.11/site-packages/transformers/models/auto/tokenization_auto.py", line 877, in from_pretrained
[rank0]:     config = AutoConfig.from_pretrained(
[rank0]:              ^^^^^^^^^^^^^^^^^^^^^^^^^^^
[rank0]:   File "/scratch/mjd9571/VentureAI/myenv/lib/python3.11/site-packages/transformers/models/auto/configuration_auto.py", line 1017, in from_pretrained
[rank0]:     config_dict, unused_kwargs = PretrainedConfig.get_config_dict(pretrained_model_name_or_path, **kwargs)
[rank0]:                                  ^^^^^^^^^^^^^^^^^^^^^^^^^^^^^^^^^^^^^^^^^^^^^^^^^^^^^^^^^^^^^^^^^^^^^^^^^
[rank0]:   File "/scratch/mjd9571/VentureAI/myenv/lib/python3.11/site-packages/transformers/configuration_utils.py", line 574, in get_config_dict
[rank0]:     config_dict, kwargs = cls._get_config_dict(pretrained_model_name_or_path, **kwargs)
[rank0]:                           ^^^^^^^^^^^^^^^^^^^^^^^^^^^^^^^^^^^^^^^^^^^^^^^^^^^^^^^^^^^^^
[rank0]:   File "/scratch/mjd9571/VentureAI/myenv/lib/python3.11/site-packages/transformers/configuration_utils.py", line 633, in _get_config_dict
[rank0]:     resolved_config_file = cached_file(
[rank0]:                            ^^^^^^^^^^^^
[rank0]:   File "/scratch/mjd9571/VentureAI/myenv/lib/python3.11/site-packages/transformers/utils/hub.py", line 421, in cached_file
[rank0]:     raise EnvironmentError(
[rank0]: OSError: You are trying to access a gated repo.
[rank0]: Make sure to have access to it at https://huggingface.co/meta-llama/Llama-3.1-8B-Instruct.
[rank0]: 401 Client Error. (Request ID: Root=1-67561cd2-54b7270a10117f1072dd3532;b521bbe2-302c-470c-8f96-63a57421d8f2)

[rank0]: Cannot access gated repo for url https://huggingface.co/meta-llama/Llama-3.1-8B-Instruct/resolve/main/config.json.
[rank0]: Access to model meta-llama/Llama-3.1-8B-Instruct is restricted. You must have access to it and be authenticated to access it. Please log in.
[rank3]: Traceback (most recent call last):
[rank3]:   File "/scratch/mjd9571/VentureAI/myenv/lib/python3.11/site-packages/huggingface_hub/utils/_http.py", line 406, in hf_raise_for_status
[rank3]:     response.raise_for_status()
[rank3]:   File "/scratch/mjd9571/VentureAI/myenv/lib/python3.11/site-packages/requests/models.py", line 1024, in raise_for_status
[rank3]:     raise HTTPError(http_error_msg, response=self)
[rank3]: requests.exceptions.HTTPError: 401 Client Error: Unauthorized for url: https://huggingface.co/meta-llama/Llama-3.1-8B-Instruct/resolve/main/config.json

[rank3]: The above exception was the direct cause of the following exception:

[rank3]: Traceback (most recent call last):
[rank3]:   File "/scratch/mjd9571/VentureAI/myenv/lib/python3.11/site-packages/transformers/utils/hub.py", line 403, in cached_file
[rank3]:     resolved_file = hf_hub_download(
[rank3]:                     ^^^^^^^^^^^^^^^^
[rank3]:   File "/scratch/mjd9571/VentureAI/myenv/lib/python3.11/site-packages/huggingface_hub/utils/_validators.py", line 114, in _inner_fn
[rank3]:     return fn(*args, **kwargs)
[rank3]:            ^^^^^^^^^^^^^^^^^^^
[rank3]:   File "/scratch/mjd9571/VentureAI/myenv/lib/python3.11/site-packages/huggingface_hub/file_download.py", line 862, in hf_hub_download
[rank3]:     return _hf_hub_download_to_cache_dir(
[rank3]:            ^^^^^^^^^^^^^^^^^^^^^^^^^^^^^^
[rank3]:   File "/scratch/mjd9571/VentureAI/myenv/lib/python3.11/site-packages/huggingface_hub/file_download.py", line 969, in _hf_hub_download_to_cache_dir
[rank3]:     _raise_on_head_call_error(head_call_error, force_download, local_files_only)
[rank3]:   File "/scratch/mjd9571/VentureAI/myenv/lib/python3.11/site-packages/huggingface_hub/file_download.py", line 1484, in _raise_on_head_call_error
[rank3]:     raise head_call_error
[rank3]:   File "/scratch/mjd9571/VentureAI/myenv/lib/python3.11/site-packages/huggingface_hub/file_download.py", line 1376, in _get_metadata_or_catch_error
[rank3]:     metadata = get_hf_file_metadata(
[rank3]:                ^^^^^^^^^^^^^^^^^^^^^
[rank3]:   File "/scratch/mjd9571/VentureAI/myenv/lib/python3.11/site-packages/huggingface_hub/utils/_validators.py", line 114, in _inner_fn
[rank3]:     return fn(*args, **kwargs)
[rank3]:            ^^^^^^^^^^^^^^^^^^^
[rank3]:   File "/scratch/mjd9571/VentureAI/myenv/lib/python3.11/site-packages/huggingface_hub/file_download.py", line 1296, in get_hf_file_metadata
[rank3]:     r = _request_wrapper(
[rank3]:         ^^^^^^^^^^^^^^^^^
[rank3]:   File "/scratch/mjd9571/VentureAI/myenv/lib/python3.11/site-packages/huggingface_hub/file_download.py", line 277, in _request_wrapper
[rank3]:     response = _request_wrapper(
[rank3]:                ^^^^^^^^^^^^^^^^^
[rank3]:   File "/scratch/mjd9571/VentureAI/myenv/lib/python3.11/site-packages/huggingface_hub/file_download.py", line 301, in _request_wrapper
[rank3]:     hf_raise_for_status(response)
[rank3]:   File "/scratch/mjd9571/VentureAI/myenv/lib/python3.11/site-packages/huggingface_hub/utils/_http.py", line 423, in hf_raise_for_status
[rank3]:     raise _format(GatedRepoError, message, response) from e
[rank3]: huggingface_hub.errors.GatedRepoError: 401 Client Error. (Request ID: Root=1-67561cd2-36dc334b6379f15b0d8787b3;b9af36f6-1fba-4ec1-9d2b-1fdf914c4e66)

[rank3]: Cannot access gated repo for url https://huggingface.co/meta-llama/Llama-3.1-8B-Instruct/resolve/main/config.json.
[rank3]: Access to model meta-llama/Llama-3.1-8B-Instruct is restricted. You must have access to it and be authenticated to access it. Please log in.

[rank3]: The above exception was the direct cause of the following exception:

[rank3]: Traceback (most recent call last):
[rank3]:   File "/scratch/mjd9571/VentureAI/fine_tuning/llamainstruct.py", line 619, in <module>
[rank3]:     main()
[rank3]:   File "/scratch/mjd9571/VentureAI/fine_tuning/llamainstruct.py", line 254, in main
[rank3]:     tokenizer = AutoTokenizer.from_pretrained(model_name)
[rank3]:                 ^^^^^^^^^^^^^^^^^^^^^^^^^^^^^^^^^^^^^^^^^
[rank3]:   File "/scratch/mjd9571/VentureAI/myenv/lib/python3.11/site-packages/transformers/models/auto/tokenization_auto.py", line 877, in from_pretrained
[rank3]:     config = AutoConfig.from_pretrained(
[rank3]:              ^^^^^^^^^^^^^^^^^^^^^^^^^^^
[rank3]:   File "/scratch/mjd9571/VentureAI/myenv/lib/python3.11/site-packages/transformers/models/auto/configuration_auto.py", line 1017, in from_pretrained
[rank3]:     config_dict, unused_kwargs = PretrainedConfig.get_config_dict(pretrained_model_name_or_path, **kwargs)
[rank3]:                                  ^^^^^^^^^^^^^^^^^^^^^^^^^^^^^^^^^^^^^^^^^^^^^^^^^^^^^^^^^^^^^^^^^^^^^^^^^
[rank3]:   File "/scratch/mjd9571/VentureAI/myenv/lib/python3.11/site-packages/transformers/configuration_utils.py", line 574, in get_config_dict
[rank3]:     config_dict, kwargs = cls._get_config_dict(pretrained_model_name_or_path, **kwargs)
[rank3]:                           ^^^^^^^^^^^^^^^^^^^^^^^^^^^^^^^^^^^^^^^^^^^^^^^^^^^^^^^^^^^^^
[rank3]:   File "/scratch/mjd9571/VentureAI/myenv/lib/python3.11/site-packages/transformers/configuration_utils.py", line 633, in _get_config_dict
[rank3]:     resolved_config_file = cached_file(
[rank3]:                            ^^^^^^^^^^^^
[rank3]:   File "/scratch/mjd9571/VentureAI/myenv/lib/python3.11/site-packages/transformers/utils/hub.py", line 421, in cached_file
[rank3]:     raise EnvironmentError(
[rank3]: OSError: You are trying to access a gated repo.
[rank3]: Make sure to have access to it at https://huggingface.co/meta-llama/Llama-3.1-8B-Instruct.
[rank3]: 401 Client Error. (Request ID: Root=1-67561cd2-36dc334b6379f15b0d8787b3;b9af36f6-1fba-4ec1-9d2b-1fdf914c4e66)

[rank3]: Cannot access gated repo for url https://huggingface.co/meta-llama/Llama-3.1-8B-Instruct/resolve/main/config.json.
[rank3]: Access to model meta-llama/Llama-3.1-8B-Instruct is restricted. You must have access to it and be authenticated to access it. Please log in.
[rank1]: Traceback (most recent call last):
[rank1]:   File "/scratch/mjd9571/VentureAI/myenv/lib/python3.11/site-packages/huggingface_hub/utils/_http.py", line 406, in hf_raise_for_status
[rank1]:     response.raise_for_status()
[rank1]:   File "/scratch/mjd9571/VentureAI/myenv/lib/python3.11/site-packages/requests/models.py", line 1024, in raise_for_status
[rank1]:     raise HTTPError(http_error_msg, response=self)
[rank1]: requests.exceptions.HTTPError: 401 Client Error: Unauthorized for url: https://huggingface.co/meta-llama/Llama-3.1-8B-Instruct/resolve/main/config.json

[rank1]: The above exception was the direct cause of the following exception:

[rank1]: Traceback (most recent call last):
[rank1]:   File "/scratch/mjd9571/VentureAI/myenv/lib/python3.11/site-packages/transformers/utils/hub.py", line 403, in cached_file
[rank1]:     resolved_file = hf_hub_download(
[rank1]:                     ^^^^^^^^^^^^^^^^
[rank1]:   File "/scratch/mjd9571/VentureAI/myenv/lib/python3.11/site-packages/huggingface_hub/utils/_validators.py", line 114, in _inner_fn
[rank1]:     return fn(*args, **kwargs)
[rank1]:            ^^^^^^^^^^^^^^^^^^^
[rank1]:   File "/scratch/mjd9571/VentureAI/myenv/lib/python3.11/site-packages/huggingface_hub/file_download.py", line 862, in hf_hub_download
[rank1]:     return _hf_hub_download_to_cache_dir(
[rank1]:            ^^^^^^^^^^^^^^^^^^^^^^^^^^^^^^
[rank1]:   File "/scratch/mjd9571/VentureAI/myenv/lib/python3.11/site-packages/huggingface_hub/file_download.py", line 969, in _hf_hub_download_to_cache_dir
[rank1]:     _raise_on_head_call_error(head_call_error, force_download, local_files_only)
[rank1]:   File "/scratch/mjd9571/VentureAI/myenv/lib/python3.11/site-packages/huggingface_hub/file_download.py", line 1484, in _raise_on_head_call_error
[rank1]:     raise head_call_error
[rank1]:   File "/scratch/mjd9571/VentureAI/myenv/lib/python3.11/site-packages/huggingface_hub/file_download.py", line 1376, in _get_metadata_or_catch_error
[rank1]:     metadata = get_hf_file_metadata(
[rank1]:                ^^^^^^^^^^^^^^^^^^^^^
[rank1]:   File "/scratch/mjd9571/VentureAI/myenv/lib/python3.11/site-packages/huggingface_hub/utils/_validators.py", line 114, in _inner_fn
[rank1]:     return fn(*args, **kwargs)
[rank1]:            ^^^^^^^^^^^^^^^^^^^
[rank1]:   File "/scratch/mjd9571/VentureAI/myenv/lib/python3.11/site-packages/huggingface_hub/file_download.py", line 1296, in get_hf_file_metadata
[rank1]:     r = _request_wrapper(
[rank1]:         ^^^^^^^^^^^^^^^^^
[rank1]:   File "/scratch/mjd9571/VentureAI/myenv/lib/python3.11/site-packages/huggingface_hub/file_download.py", line 277, in _request_wrapper
[rank1]:     response = _request_wrapper(
[rank1]:                ^^^^^^^^^^^^^^^^^
[rank1]:   File "/scratch/mjd9571/VentureAI/myenv/lib/python3.11/site-packages/huggingface_hub/file_download.py", line 301, in _request_wrapper
[rank1]:     hf_raise_for_status(response)
[rank1]:   File "/scratch/mjd9571/VentureAI/myenv/lib/python3.11/site-packages/huggingface_hub/utils/_http.py", line 423, in hf_raise_for_status
[rank1]:     raise _format(GatedRepoError, message, response) from e
[rank1]: huggingface_hub.errors.GatedRepoError: 401 Client Error. (Request ID: Root=1-67561cd2-12843a355bd451db7744fb05;7686c8df-b316-43aa-94ae-755cc6e7544e)

[rank1]: Cannot access gated repo for url https://huggingface.co/meta-llama/Llama-3.1-8B-Instruct/resolve/main/config.json.
[rank1]: Access to model meta-llama/Llama-3.1-8B-Instruct is restricted. You must have access to it and be authenticated to access it. Please log in.

[rank1]: The above exception was the direct cause of the following exception:

[rank1]: Traceback (most recent call last):
[rank1]:   File "/scratch/mjd9571/VentureAI/fine_tuning/llamainstruct.py", line 619, in <module>
[rank1]:     main()
[rank1]:   File "/scratch/mjd9571/VentureAI/fine_tuning/llamainstruct.py", line 254, in main
[rank1]:     tokenizer = AutoTokenizer.from_pretrained(model_name)
[rank1]:                 ^^^^^^^^^^^^^^^^^^^^^^^^^^^^^^^^^^^^^^^^^
[rank1]:   File "/scratch/mjd9571/VentureAI/myenv/lib/python3.11/site-packages/transformers/models/auto/tokenization_auto.py", line 877, in from_pretrained
[rank1]:     config = AutoConfig.from_pretrained(
[rank1]:              ^^^^^^^^^^^^^^^^^^^^^^^^^^^
[rank1]:   File "/scratch/mjd9571/VentureAI/myenv/lib/python3.11/site-packages/transformers/models/auto/configuration_auto.py", line 1017, in from_pretrained
[rank1]:     config_dict, unused_kwargs = PretrainedConfig.get_config_dict(pretrained_model_name_or_path, **kwargs)
[rank1]:                                  ^^^^^^^^^^^^^^^^^^^^^^^^^^^^^^^^^^^^^^^^^^^^^^^^^^^^^^^^^^^^^^^^^^^^^^^^^
[rank1]:   File "/scratch/mjd9571/VentureAI/myenv/lib/python3.11/site-packages/transformers/configuration_utils.py", line 574, in get_config_dict
[rank1]:     config_dict, kwargs = cls._get_config_dict(pretrained_model_name_or_path, **kwargs)
[rank1]:                           ^^^^^^^^^^^^^^^^^^^^^^^^^^^^^^^^^^^^^^^^^^^^^^^^^^^^^^^^^^^^^
[rank1]:   File "/scratch/mjd9571/VentureAI/myenv/lib/python3.11/site-packages/transformers/configuration_utils.py", line 633, in _get_config_dict
[rank1]:     resolved_config_file = cached_file(
[rank1]:                            ^^^^^^^^^^^^
[rank1]:   File "/scratch/mjd9571/VentureAI/myenv/lib/python3.11/site-packages/transformers/utils/hub.py", line 421, in cached_file
[rank1]:     raise EnvironmentError(
[rank1]: OSError: You are trying to access a gated repo.
[rank1]: Make sure to have access to it at https://huggingface.co/meta-llama/Llama-3.1-8B-Instruct.
[rank1]: 401 Client Error. (Request ID: Root=1-67561cd2-12843a355bd451db7744fb05;7686c8df-b316-43aa-94ae-755cc6e7544e)

[rank1]: Cannot access gated repo for url https://huggingface.co/meta-llama/Llama-3.1-8B-Instruct/resolve/main/config.json.
[rank1]: Access to model meta-llama/Llama-3.1-8B-Instruct is restricted. You must have access to it and be authenticated to access it. Please log in.
[rank2]: Traceback (most recent call last):
[rank2]:   File "/scratch/mjd9571/VentureAI/myenv/lib/python3.11/site-packages/huggingface_hub/utils/_http.py", line 406, in hf_raise_for_status
[rank2]:     response.raise_for_status()
[rank2]:   File "/scratch/mjd9571/VentureAI/myenv/lib/python3.11/site-packages/requests/models.py", line 1024, in raise_for_status
[rank2]:     raise HTTPError(http_error_msg, response=self)
[rank2]: requests.exceptions.HTTPError: 401 Client Error: Unauthorized for url: https://huggingface.co/meta-llama/Llama-3.1-8B-Instruct/resolve/main/config.json

[rank2]: The above exception was the direct cause of the following exception:

[rank2]: Traceback (most recent call last):
[rank2]:   File "/scratch/mjd9571/VentureAI/myenv/lib/python3.11/site-packages/transformers/utils/hub.py", line 403, in cached_file
[rank2]:     resolved_file = hf_hub_download(
[rank2]:                     ^^^^^^^^^^^^^^^^
[rank2]:   File "/scratch/mjd9571/VentureAI/myenv/lib/python3.11/site-packages/huggingface_hub/utils/_validators.py", line 114, in _inner_fn
[rank2]:     return fn(*args, **kwargs)
[rank2]:            ^^^^^^^^^^^^^^^^^^^
[rank2]:   File "/scratch/mjd9571/VentureAI/myenv/lib/python3.11/site-packages/huggingface_hub/file_download.py", line 862, in hf_hub_download
[rank2]:     return _hf_hub_download_to_cache_dir(
[rank2]:            ^^^^^^^^^^^^^^^^^^^^^^^^^^^^^^
[rank2]:   File "/scratch/mjd9571/VentureAI/myenv/lib/python3.11/site-packages/huggingface_hub/file_download.py", line 969, in _hf_hub_download_to_cache_dir
[rank2]:     _raise_on_head_call_error(head_call_error, force_download, local_files_only)
[rank2]:   File "/scratch/mjd9571/VentureAI/myenv/lib/python3.11/site-packages/huggingface_hub/file_download.py", line 1484, in _raise_on_head_call_error
[rank2]:     raise head_call_error
[rank2]:   File "/scratch/mjd9571/VentureAI/myenv/lib/python3.11/site-packages/huggingface_hub/file_download.py", line 1376, in _get_metadata_or_catch_error
[rank2]:     metadata = get_hf_file_metadata(
[rank2]:                ^^^^^^^^^^^^^^^^^^^^^
[rank2]:   File "/scratch/mjd9571/VentureAI/myenv/lib/python3.11/site-packages/huggingface_hub/utils/_validators.py", line 114, in _inner_fn
[rank2]:     return fn(*args, **kwargs)
[rank2]:            ^^^^^^^^^^^^^^^^^^^
[rank2]:   File "/scratch/mjd9571/VentureAI/myenv/lib/python3.11/site-packages/huggingface_hub/file_download.py", line 1296, in get_hf_file_metadata
[rank2]:     r = _request_wrapper(
[rank2]:         ^^^^^^^^^^^^^^^^^
[rank2]:   File "/scratch/mjd9571/VentureAI/myenv/lib/python3.11/site-packages/huggingface_hub/file_download.py", line 277, in _request_wrapper
[rank2]:     response = _request_wrapper(
[rank2]:                ^^^^^^^^^^^^^^^^^
[rank2]:   File "/scratch/mjd9571/VentureAI/myenv/lib/python3.11/site-packages/huggingface_hub/file_download.py", line 301, in _request_wrapper
[rank2]:     hf_raise_for_status(response)
[rank2]:   File "/scratch/mjd9571/VentureAI/myenv/lib/python3.11/site-packages/huggingface_hub/utils/_http.py", line 423, in hf_raise_for_status
[rank2]:     raise _format(GatedRepoError, message, response) from e
[rank2]: huggingface_hub.errors.GatedRepoError: 401 Client Error. (Request ID: Root=1-67561cd2-290353f55840237c3bb426f6;5f32fbf1-99c4-484c-a502-3b9da58896d0)

[rank2]: Cannot access gated repo for url https://huggingface.co/meta-llama/Llama-3.1-8B-Instruct/resolve/main/config.json.
[rank2]: Access to model meta-llama/Llama-3.1-8B-Instruct is restricted. You must have access to it and be authenticated to access it. Please log in.

[rank2]: The above exception was the direct cause of the following exception:

[rank2]: Traceback (most recent call last):
[rank2]:   File "/scratch/mjd9571/VentureAI/fine_tuning/llamainstruct.py", line 619, in <module>
[rank2]:     main()
[rank2]:   File "/scratch/mjd9571/VentureAI/fine_tuning/llamainstruct.py", line 254, in main
[rank2]:     tokenizer = AutoTokenizer.from_pretrained(model_name)
[rank2]:                 ^^^^^^^^^^^^^^^^^^^^^^^^^^^^^^^^^^^^^^^^^
[rank2]:   File "/scratch/mjd9571/VentureAI/myenv/lib/python3.11/site-packages/transformers/models/auto/tokenization_auto.py", line 877, in from_pretrained
[rank2]:     config = AutoConfig.from_pretrained(
[rank2]:              ^^^^^^^^^^^^^^^^^^^^^^^^^^^
[rank2]:   File "/scratch/mjd9571/VentureAI/myenv/lib/python3.11/site-packages/transformers/models/auto/configuration_auto.py", line 1017, in from_pretrained
[rank2]:     config_dict, unused_kwargs = PretrainedConfig.get_config_dict(pretrained_model_name_or_path, **kwargs)
[rank2]:                                  ^^^^^^^^^^^^^^^^^^^^^^^^^^^^^^^^^^^^^^^^^^^^^^^^^^^^^^^^^^^^^^^^^^^^^^^^^
[rank2]:   File "/scratch/mjd9571/VentureAI/myenv/lib/python3.11/site-packages/transformers/configuration_utils.py", line 574, in get_config_dict
[rank2]:     config_dict, kwargs = cls._get_config_dict(pretrained_model_name_or_path, **kwargs)
[rank2]:                           ^^^^^^^^^^^^^^^^^^^^^^^^^^^^^^^^^^^^^^^^^^^^^^^^^^^^^^^^^^^^^
[rank2]:   File "/scratch/mjd9571/VentureAI/myenv/lib/python3.11/site-packages/transformers/configuration_utils.py", line 633, in _get_config_dict
[rank2]:     resolved_config_file = cached_file(
[rank2]:                            ^^^^^^^^^^^^
[rank2]:   File "/scratch/mjd9571/VentureAI/myenv/lib/python3.11/site-packages/transformers/utils/hub.py", line 421, in cached_file
[rank2]:     raise EnvironmentError(
[rank2]: OSError: You are trying to access a gated repo.
[rank2]: Make sure to have access to it at https://huggingface.co/meta-llama/Llama-3.1-8B-Instruct.
[rank2]: 401 Client Error. (Request ID: Root=1-67561cd2-290353f55840237c3bb426f6;5f32fbf1-99c4-484c-a502-3b9da58896d0)

[rank2]: Cannot access gated repo for url https://huggingface.co/meta-llama/Llama-3.1-8B-Instruct/resolve/main/config.json.
[rank2]: Access to model meta-llama/Llama-3.1-8B-Instruct is restricted. You must have access to it and be authenticated to access it. Please log in.
W1208 17:25:23.460000 3559354 torch/distributed/elastic/multiprocessing/api.py:897] Sending process 3559360 closing signal SIGTERM
W1208 17:25:23.460000 3559354 torch/distributed/elastic/multiprocessing/api.py:897] Sending process 3559361 closing signal SIGTERM
W1208 17:25:23.460000 3559354 torch/distributed/elastic/multiprocessing/api.py:897] Sending process 3559362 closing signal SIGTERM
E1208 17:25:23.602000 3559354 torch/distributed/elastic/multiprocessing/api.py:869] failed (exitcode: 1) local_rank: 0 (pid: 3559359) of binary: /scratch/mjd9571/VentureAI/myenv/bin/python
Traceback (most recent call last):
  File "/scratch/mjd9571/VentureAI/myenv/bin/torchrun", line 8, in <module>
    sys.exit(main())
             ^^^^^^
  File "/scratch/mjd9571/VentureAI/myenv/lib/python3.11/site-packages/torch/distributed/elastic/multiprocessing/errors/__init__.py", line 355, in wrapper
    return f(*args, **kwargs)
           ^^^^^^^^^^^^^^^^^^
  File "/scratch/mjd9571/VentureAI/myenv/lib/python3.11/site-packages/torch/distributed/run.py", line 919, in main
    run(args)
  File "/scratch/mjd9571/VentureAI/myenv/lib/python3.11/site-packages/torch/distributed/run.py", line 910, in run
    elastic_launch(
  File "/scratch/mjd9571/VentureAI/myenv/lib/python3.11/site-packages/torch/distributed/launcher/api.py", line 138, in __call__
    return launch_agent(self._config, self._entrypoint, list(args))
           ^^^^^^^^^^^^^^^^^^^^^^^^^^^^^^^^^^^^^^^^^^^^^^^^^^^^^^^^
  File "/scratch/mjd9571/VentureAI/myenv/lib/python3.11/site-packages/torch/distributed/launcher/api.py", line 269, in launch_agent
    raise ChildFailedError(
torch.distributed.elastic.multiprocessing.errors.ChildFailedError: 
============================================================
llamainstruct.py FAILED
------------------------------------------------------------
Failures:
  <NO_OTHER_FAILURES>
------------------------------------------------------------
Root Cause (first observed failure):
[0]:
  time      : 2024-12-08_17:25:23
  host      : gr047.hpc.nyu.edu
  rank      : 0 (local_rank: 0)
  exitcode  : 1 (pid: 3559359)
  error_file: <N/A>
  traceback : To enable traceback see: https://pytorch.org/docs/stable/elastic/errors.html
============================================================
